Workbook

Sheet Risk_Assessment
B2: Sr.No | C2: Asset | D2: Threat | E2: Consequence | F2: Impact | L2: Likelihood | O2: Unmitiagted Risk | P2: SL-T | Q2: Countermeasures | R2: Likelihood After Mitigation
F3: Bussiness (Reputation) | G3: Operational (Loss of Data) | H3: Financial (Operational Disruption) | I3: Safety (Physical Harm) | J3: Environmental Impact | K3: Final Impact | L3: Asset Exposure Index | M3: Threat Exploitation feasibiity | N3: Unmitiagted Threat Liklihood | R3: Asset Exposure Index | S3: Threat Exploitation feasibiity | T3: Mitigeted Threat Likelhood | U3: Mit risk
B4: 1 | C4: Operator Server | D4: Acting as a Rogue Master in Operator Server 1 | E4: An attackers device pretends to be a master controller on the network. This can be used to send unauthorized commands and override legitimate control logic. | F4: 3 | G4: 4 | H4: 3 | I4: 2 | J4: 1 | K4: =MAX(F4:J4) -> 4 | L4: Restricted Access | M4: Extreme High | N4: =CHOOSE(MATCH(INDEX($L$65:$P$69, MATCH(M4, $J$65:$J$69, 0), MATCH(L4, $L$64:$P$64, 0)), {"Very Unlikely","Unlikely","Possible","Likely","Certain"},0),1,2,3,4,5) -> 3 | O4: =K4*N4 -> 12 | P4: =VLOOKUP(O4,SLTS!$A$1:$B$27,2) -> 2 | Q4: Host-based allowlists; restrict masters; authentication and authorization for masters; monitor masters. | R4: Highly Restricted | S4: Low | T4: =CHOOSE(MATCH(INDEX($L$65:$P$69, MATCH(S4, $J$65:$J$69, 0), MATCH(R4, $L$64:$P$64, 0)), {"Very Unlikely","Unlikely","Possible","Likely","Certain"},0),1,2,3,4,5) -> 2 | U4: =max(F4:J4)*T4 -> 8 | X4: SL Levels | Y4: Threats counts
B5: 2 | C5: PLC | D5: Activating Firmware Update Mode Abuse in PLC 1 | E5: An attacker forces a device into its firmware update state. This can be used to install malicious firmware or disable the device entirely. | F5: 3 | G5: 4 | H5: 4 | I5: 3 | J5: 2 | K5: =MAX(F5:J5) -> 4 | L5: Restricted Access | M5: Extreme High | N5: =CHOOSE(MATCH(INDEX($L$65:$P$69, MATCH(M5, $J$65:$J$69, 0), MATCH(L5, $L$64:$P$64, 0)), {"Very Unlikely","Unlikely","Possible","Likely","Certain"},0),1,2,3,4,5) -> 3 | O5: =K5*N5 -> 12 | P5: =VLOOKUP(O5,SLTS!$A$1:$B$27,2) -> 2 | Q5: Restrict update modes to authenticated/authorized hosts; signed update packages; physical controls. | R5: Completely Isolated | S5: Low | T5: =CHOOSE(MATCH(INDEX($L$65:$P$69, MATCH(S5, $J$65:$J$69, 0), MATCH(R5, $L$64:$P$64, 0)), {"Very Unlikely","Unlikely","Possible","Likely","Certain"},0),1,2,3,4,5) -> 1 | U5: =max(F5:J5)*T5 -> 4 | X5: 1 | Y5: 1 | Z5: 27
B6: 3 | C6: Operator Server | D6: Authentication Bypass By Message Replay | E6: An attacker can capture and replay a legitimate authentication message. This can be used to bypass authentication and gain unauthorized access. | F6: 3 | G6: 3 | H6: 4 | I6: 3 | J6: 3 | K6: =MAX(F6:J6) -> 4 | L6: Easily Accessible | M6: High | N6: =CHOOSE(MATCH(INDEX($L$65:$P$69, MATCH(M6, $J$65:$J$69, 0), MATCH(L6, $L$64:$P$64, 0)), {"Very Unlikely","Unlikely","Possible","Likely","Certain"},0),1,2,3,4,5) -> 3 | O6: =K6*N6 -> 12 | P6: =VLOOKUP(O6,SLTS!$A$1:$B$27,2) -> 2 | Q6: Harden auth flows; secure credential storage; enforce MFA; log changes. | R6: Restricted Access | S6: Low | T6: =CHOOSE(MATCH(INDEX($L$65:$P$69, MATCH(S6, $J$65:$J$69, 0), MATCH(R6, $L$64:$P$64, 0)), {"Very Unlikely","Unlikely","Possible","Likely","Certain"},0),1,2,3,4,5) -> 2 | U6: =max(F6:J6)*T6 -> 8 | X6: 2 | Y6: 34
B7: 4 | C7: Operator Server | D7: Causing Denial of Control over Operator Server 1 | E7: The attacker takes control of the system away from the legitimate user. This is a direct consequence of a successful attack on an ICS. | F7: 3 | G7: 4 | H7: 4 | I7: 3 | J7: 3 | K7: =MAX(F7:J7) -> 4 | L7: Easily Accessible | M7: High | N7: =CHOOSE(MATCH(INDEX($L$65:$P$69, MATCH(M7, $J$65:$J$69, 0), MATCH(L7, $L$64:$P$64, 0)), {"Very Unlikely","Unlikely","Possible","Likely","Certain"},0),1,2,3,4,5) -> 3 | O7: =K7*N7 -> 12 | P7: =VLOOKUP(O7,SLTS!$A$1:$B$27,2) -> 2 | Q7: Same as Loss of Control â€” authentication, redundancy, monitoring. | R7: Restricted Access | S7: Low | T7: =CHOOSE(MATCH(INDEX($L$65:$P$69, MATCH(S7, $J$65:$J$69, 0), MATCH(R7, $L$64:$P$64, 0)), {"Very Unlikely","Unlikely","Possible","Likely","Certain"},0),1,2,3,4,5) -> 2 | U7: =max(F7:J7)*T7 -> 8 | X7: 3 | Y7: 9
B8: 5 | C8: PLC | D8: Causing Denial of Service for Web Server in PLC 1 | E8: An attacker floods a web server with traffic, making it unavailable. This can be used to prevent operators from accessing critical management interfaces. | F8: 3 | G8: 4 | H8: 4 | I8: 4 | J8: 3 | K8: =MAX(F8:J8) -> 4 | L8: Restricted Access | M8: Extreme High | N8: =CHOOSE(MATCH(INDEX($L$65:$P$69, MATCH(M8, $J$65:$J$69, 0), MATCH(L8, $L$64:$P$64, 0)), {"Very Unlikely","Unlikely","Possible","Likely","Certain"},0),1,2,3,4,5) -> 3 | O8: =max(F8:J8)*N8 -> 12 | P8: =VLOOKUP(O8,SLTS!$A$1:$B$27,2) -> 2 | Q8: Rate-limiting, WAF, patching, web server hardening, upstream DDoS protection. | R8: Completely Isolated | S8: Medium | T8: =CHOOSE(MATCH(INDEX($L$65:$P$69, MATCH(S8, $J$65:$J$69, 0), MATCH(R8, $L$64:$P$64, 0)), {"Very Unlikely","Unlikely","Possible","Likely","Certain"},0),1,2,3,4,5) -> 2 | U8: =max(F8:J8)*T8 -> 8 | X8: 4 | Y8: 3
B9: 6 | C9: Operator Server | D9: Causing loss of Productivity and Revenue in Operator Server 1 | E9: The business impact of a successful attack. This is a consequence of a loss of availability or control. | F9: 4 | G9: 4 | H9: 4 | I9: 3 | J9: 3 | K9: =MAX(F9:J9) -> 4 | L9: Easily Accessible | M9: Medium | N9: =CHOOSE(MATCH(INDEX($L$65:$P$69, MATCH(M9, $J$65:$J$69, 0), MATCH(L9, $L$64:$P$64, 0)), {"Very Unlikely","Unlikely","Possible","Likely","Certain"},0),1,2,3,4,5) -> 3 | O9: =max(F9:J9)*N9 -> 12 | P9: =VLOOKUP(O9,SLTS!$A$1:$B$27,2) -> 2 | Q9: Business continuity planning; backups; rapid incident response. | R9: Completely Isolated | S9: Medium | T9: =CHOOSE(MATCH(INDEX($L$65:$P$69, MATCH(S9, $J$65:$J$69, 0), MATCH(R9, $L$64:$P$64, 0)), {"Very Unlikely","Unlikely","Possible","Likely","Certain"},0),1,2,3,4,5) -> 2 | U9: =max(F9:J9)*T9 -> 8 | Y9: =sum(Y5:Y8) -> 47
B10: 7 | C10: Operator Server | D10: Changing Credentials to escalate privileges in Operator Server 1 | E10: An attacker forces a change in a device's credentials. This can lock out legitimate users, granting the attacker exclusive access. | F10: 3 | G10: 4 | H10: 4 | I10: 4 | J10: 3 | K10: =MAX(F10:J10) -> 4 | L10: Restricted Access | M10: High | N10: =CHOOSE(MATCH(INDEX($L$65:$P$69, MATCH(M10, $J$65:$J$69, 0), MATCH(L10, $L$64:$P$64, 0)), {"Very Unlikely","Unlikely","Possible","Likely","Certain"},0),1,2,3,4,5) -> 3 | O10: =max(F10:J10)*N10 -> 12 | P10: =VLOOKUP(O10,SLTS!$A$1:$B$27,2) -> 2 | Q10: Credential management policies; MFA; authenticated admin channels; audit trails. | R10: Highly Restricted | S10: Low | T10: =CHOOSE(MATCH(INDEX($L$65:$P$69, MATCH(S10, $J$65:$J$69, 0), MATCH(R10, $L$64:$P$64, 0)), {"Very Unlikely","Unlikely","Possible","Likely","Certain"},0),1,2,3,4,5) -> 2 | U10: =max(F10:J10)*T10 -> 8
B11: 8 | C11: PLC | D11: Changing Operating Mode in PLC 1 | E11: An attacker changes the operational mode of a device. This can be used to take a device offline, put it in a maintenance state, or disable safety functions. | F11: 3 | G11: 3 | H11: 4 | I11: 2 | J11: 2 | K11: =MAX(F11:J11) -> 4 | L11: Highly Restricted | M11: Extreme High | N11: =CHOOSE(MATCH(INDEX($L$65:$P$69, MATCH(M11, $J$65:$J$69, 0), MATCH(L11, $L$64:$P$64, 0)), {"Very Unlikely","Unlikely","Possible","Likely","Certain"},0),1,2,3,4,5) -> 3 | O11: =max(F11:J11)*N11 -> 12 | P11: =VLOOKUP(O11,SLTS!$A$1:$B$27,2) -> 2 | Q11: Enforce authentication & authorization for mode changes; audit & alerts; confirm through secure channels. | R11: Completely Isolated | S11: Low | T11: =CHOOSE(MATCH(INDEX($L$65:$P$69, MATCH(S11, $J$65:$J$69, 0), MATCH(R11, $L$64:$P$64, 0)), {"Very Unlikely","Unlikely","Possible","Likely","Certain"},0),1,2,3,4,5) -> 1 | U11: =max(F11:J11)*T11 -> 4
B12: 9 | C12: Operator Server | D12: Communicating over a Commonly Used Port to evade detection in Operator Server 1 | E12: Using a known port can lead to unauthorized access. This allows an attacker to bypass firewalls and security controls, initiating further attacks. | F12: 3 | G12: 4 | H12: 4 | I12: 3 | J12: 2 | K12: =MAX(F12:J12) -> 4 | L12: Restricted Access | M12: Medium | N12: =CHOOSE(MATCH(INDEX($L$65:$P$69, MATCH(M12, $J$65:$J$69, 0), MATCH(L12, $L$64:$P$64, 0)), {"Very Unlikely","Unlikely","Possible","Likely","Certain"},0),1,2,3,4,5) -> 2 | O12: =max(F12:J12)*N12 -> 8 | P12: =VLOOKUP(O12,SLTS!$A$1:$B$27,2) -> 2 | Q12: Restrict/monitor ports; firewall/ACLs; network segmentation; block unused services. | R12: Highly Restricted | S12: Low | T12: =CHOOSE(MATCH(INDEX($L$65:$P$69, MATCH(S12, $J$65:$J$69, 0), MATCH(R12, $L$64:$P$64, 0)), {"Very Unlikely","Unlikely","Possible","Likely","Certain"},0),1,2,3,4,5) -> 2 | U12: =max(F12:J12)*T12 -> 8
B13: 10 | C13: Operator Server | D13: Conducting a Denial-of-Service attack against Operator Server 1 | E13: An attack designed to make a device or service unavailable. This can be achieved by flooding it with traffic or exploiting a vulnerability that causes it to crash. | F13: 4 | G13: 3 | H13: 5 | I13: 3 | J13: 3 | K13: =MAX(F13:J13) -> 5 | L13: Easily Accessible | M13: Medium | N13: =CHOOSE(MATCH(INDEX($L$65:$P$69, MATCH(M13, $J$65:$J$69, 0), MATCH(L13, $L$64:$P$64, 0)), {"Very Unlikely","Unlikely","Possible","Likely","Certain"},0),1,2,3,4,5) -> 3 | O13: =max(F13:J13)*N13 -> 15 | P13: =VLOOKUP(O13,SLTS!$A$1:$B$27,2) -> 3 | Q13: Rate-limiting, ACLs, network filtering, DDoS protections, upstream mitigation. | R13: Restricted Access | S13: Medium | T13: =CHOOSE(MATCH(INDEX($L$65:$P$69, MATCH(S13, $J$65:$J$69, 0), MATCH(R13, $L$64:$P$64, 0)), {"Very Unlikely","Unlikely","Possible","Likely","Certain"},0),1,2,3,4,5) -> 2 | U13: =max(F13:J13)*T13 -> 10
B14: 11 | C14: Operator Server | D14: Credential Change Mechanism Can Be Abused | E14: A flaw in the process for changing credentials can be exploited by an attacker. This can be used to change a password and lock out a legitimate user. | F14: 3 | G14: 4 | H14: 4 | I14: 3 | J14: 4 | K14: =MAX(F14:J14) -> 4 | L14: Highly Restricted | M14: High | N14: =CHOOSE(MATCH(INDEX($L$65:$P$69, MATCH(M14, $J$65:$J$69, 0), MATCH(L14, $L$64:$P$64, 0)), {"Very Unlikely","Unlikely","Possible","Likely","Certain"},0),1,2,3,4,5) -> 2 | O14: =max(F14:J14)*N14 -> 8 | P14: =VLOOKUP(O14,SLTS!$A$1:$B$27,2) -> 2 | Q14: Harden credential change flows with auth, logging, approval workflows. | R14: Completely Isolated | S14: Low | T14: =CHOOSE(MATCH(INDEX($L$65:$P$69, MATCH(S14, $J$65:$J$69, 0), MATCH(R14, $L$64:$P$64, 0)), {"Very Unlikely","Unlikely","Possible","Likely","Certain"},0),1,2,3,4,5) -> 1 | U14: =max(F14:J14)*T14 -> 4
B15: 12 | C15: PLC | D15: Critical System Service May Be Disabled | E15: An attacker can disable a critical system service. This can cause a denial of service, halt a process, and lead to a loss of productivity. | F15: 4 | G15: 3 | H15: 4 | I15: 3 | J15: 3 | K15: =MAX(F15:J15) -> 4 | L15: Restricted Access | M15: High | N15: =CHOOSE(MATCH(INDEX($L$65:$P$69, MATCH(M15, $J$65:$J$69, 0), MATCH(L15, $L$64:$P$64, 0)), {"Very Unlikely","Unlikely","Possible","Likely","Certain"},0),1,2,3,4,5) -> 3 | O15: =max(F15:J15)*N15 -> 12 | P15: =VLOOKUP(O15,SLTS!$A$1:$B$27,2) -> 2 | Q15: Monitor & guard critical services; restrict who can stop services; watchdogs. | R15: Highly Restricted | S15: Low | T15: =CHOOSE(MATCH(INDEX($L$65:$P$69, MATCH(S15, $J$65:$J$69, 0), MATCH(R15, $L$64:$P$64, 0)), {"Very Unlikely","Unlikely","Possible","Likely","Certain"},0),1,2,3,4,5) -> 2 | U15: =max(F15:J15)*T15 -> 8
B16: 13 | C16: Operator Server | D16: Device leaks security information in logs | E16: A device logs sensitive security information, such as passwords or cryptographic keys. This information can be used by an attacker to compromise the device. | F16: 4 | G16: 5 | H16: 4 | I16: 3 | J16: 3 | K16: =MAX(F16:J16) -> 5 | L16: Restricted Access | M16: High | N16: =CHOOSE(MATCH(INDEX($L$65:$P$69, MATCH(M16, $J$65:$J$69, 0), MATCH(L16, $L$64:$P$64, 0)), {"Very Unlikely","Unlikely","Possible","Likely","Certain"},0),1,2,3,4,5) -> 3 | O16: =max(F16:J16)*N16 -> 15 | P16: =VLOOKUP(O16,SLTS!$A$1:$B$27,2) -> 3 | Q16: Redact sensitive info; secure log storage & transport; restrict log access. | R16: Highly Restricted | S16: Low | T16: =CHOOSE(MATCH(INDEX($L$65:$P$69, MATCH(S16, $J$65:$J$69, 0), MATCH(R16, $L$64:$P$64, 0)), {"Very Unlikely","Unlikely","Possible","Likely","Certain"},0),1,2,3,4,5) -> 2 | U16: =max(F16:J16)*T16 -> 10
B17: 14 | C17: Operator Server | D17: Enumerating Network Connections for reconnaissance in Operator Server 1 | E17: An attacker lists all active network connections. This helps them understand what devices are communicating with each other and where they might be able to intercept traffic. | F17: 3 | G17: 4 | H17: 4 | I17: 3 | J17: 2 | K17: =MAX(F17:J17) -> 4 | L17: Easily Accessible | M17: Low | N17: =CHOOSE(MATCH(INDEX($L$65:$P$69, MATCH(M17, $J$65:$J$69, 0), MATCH(L17, $L$64:$P$64, 0)), {"Very Unlikely","Unlikely","Possible","Likely","Certain"},0),1,2,3,4,5) -> 2 | O17: =max(F17:J17)*N17 -> 8 | P17: =VLOOKUP(O17,SLTS!$A$1:$B$27,2) -> 2 | Q17: Restrict/monitor net tools; host-based controls; disable unnecessary services. | R17: Highly Restricted | S17: Medium | T17: =CHOOSE(MATCH(INDEX($L$65:$P$69, MATCH(S17, $J$65:$J$69, 0), MATCH(R17, $L$64:$P$64, 0)), {"Very Unlikely","Unlikely","Possible","Likely","Certain"},0),1,2,3,4,5) -> 2 | U17: =max(F17:J17)*T17 -> 8
B18: 15 | C18: Operator Server | D18: Exploited Remote services in Operator Server 1 | E18: An attacker finds a vulnerability in a service that can be accessed from a distance. This can allow an attacker to gain unauthorized access to the network or a device. | F18: 4 | G18: 3 | H18: 4 | I18: 2 | J18: 2 | K18: =MAX(F18:J18) -> 4 | L18: Restricted Access | M18: High | N18: =CHOOSE(MATCH(INDEX($L$65:$P$69, MATCH(M18, $J$65:$J$69, 0), MATCH(L18, $L$64:$P$64, 0)), {"Very Unlikely","Unlikely","Possible","Likely","Certain"},0),1,2,3,4,5) -> 3 | O18: =max(F18:J18)*N18 -> 12 | P18: =VLOOKUP(O18,SLTS!$A$1:$B$27,2) -> 2 | Q18: Limit exposure; patching/segmentation; MFA; monitor remote activity. | R18: Completely Isolated | S18: Low | T18: =CHOOSE(MATCH(INDEX($L$65:$P$69, MATCH(S18, $J$65:$J$69, 0), MATCH(R18, $L$64:$P$64, 0)), {"Very Unlikely","Unlikely","Possible","Likely","Certain"},0),1,2,3,4,5) -> 1 | U18: =max(F18:J18)*T18 -> 4
B19: 16 | C19: Firewall | D19: Exploiting a Public-Facing Application to compromise Firewall | E19: An attacker takes advantage of a security flaw in a publicly accessible application. This can be used to gain unauthorized access to a network or system from the internet. | F19: 4 | G19: 5 | H19: 5 | I19: 4 | J19: 4 | K19: =MAX(F19:J19) -> 5 | L19: Easily Accessible | M19: High | N19: =CHOOSE(MATCH(INDEX($L$65:$P$69, MATCH(M19, $J$65:$J$69, 0), MATCH(L19, $L$64:$P$64, 0)), {"Very Unlikely","Unlikely","Possible","Likely","Certain"},0),1,2,3,4,5) -> 3 | O19: =max(F19:J19)*N19 -> 15 | P19: =VLOOKUP(O19,SLTS!$A$1:$B$27,2) -> 3 | Q19: Patch management; WAF; input validation; reduce exposure (disable test endpoints). | R19: Highly Restricted | S19: Medium | T19: =CHOOSE(MATCH(INDEX($L$65:$P$69, MATCH(S19, $J$65:$J$69, 0), MATCH(R19, $L$64:$P$64, 0)), {"Very Unlikely","Unlikely","Possible","Likely","Certain"},0),1,2,3,4,5) -> 2 | U19: =max(F19:J19)*T19 -> 10
B20: 17 | C20: PLC | D20: Exploiting Code Flaws for unauthorized access to PLC 1 | E20: An attacker finds and exploits a weakness in a program's code. This can lead to remote code execution, privilege escalation, and system compromise. | F20: 3 | G20: 3 | H20: 3 | I20: 2 | J20: 1 | K20: =MAX(F20:J20) -> 3 | L20: Highly Restricted | M20: Medium | N20: =CHOOSE(MATCH(INDEX($L$65:$P$69, MATCH(M20, $J$65:$J$69, 0), MATCH(L20, $L$64:$P$64, 0)), {"Very Unlikely","Unlikely","Possible","Likely","Certain"},0),1,2,3,4,5) -> 2 | O20: =max(F20:J20)*N20 -> 6 | P20: =VLOOKUP(O20,SLTS!$A$1:$B$27,2) -> 1 | Q20: Secure SDLC; patching; static & dynamic analysis; fuzzing; vulnerability scanning. | R20: Completely Isolated | S20: Low | T20: =CHOOSE(MATCH(INDEX($L$65:$P$69, MATCH(S20, $J$65:$J$69, 0), MATCH(R20, $L$64:$P$64, 0)), {"Very Unlikely","Unlikely","Possible","Likely","Certain"},0),1,2,3,4,5) -> 1 | U20: =max(F20:J20)*T20 -> 3
B21: 18 | C21: Operator Server | D21: Exploiting external Remote Services in Operator Server 1 | E21: A service that is exposed to the internet is a prime target for an attacker. This can provide them with a direct path to the internal network. | F21: 4 | G21: 4 | H21: 4 | I21: 2 | J21: 3 | K21: =MAX(F21:J21) -> 4 | L21: Restricted Access | M21: Extreme High | N21: =CHOOSE(MATCH(INDEX($L$65:$P$69, MATCH(M21, $J$65:$J$69, 0), MATCH(L21, $L$64:$P$64, 0)), {"Very Unlikely","Unlikely","Possible","Likely","Certain"},0),1,2,3,4,5) -> 3 | O21: =max(F21:J21)*N21 -> 12 | P21: =VLOOKUP(O21,SLTS!$A$1:$B$27,2) -> 2 | Q21: Limit remote services exposure; enforce MFA; strong config and patching. | R21: Completely Isolated | S21: Low | T21: =CHOOSE(MATCH(INDEX($L$65:$P$69, MATCH(S21, $J$65:$J$69, 0), MATCH(R21, $L$64:$P$64, 0)), {"Very Unlikely","Unlikely","Possible","Likely","Certain"},0),1,2,3,4,5) -> 1 | U21: =max(F21:J21)*T21 -> 4
... B50: 47 | C50: Operator Server | D50: Using Hooking Techniques for malicious actions in Operator Server 1 | E50: An attacker intercepts calls to a program or operating system function. This can be used to modify the behavior of a program or to steal data. | F50: 3 | G50: 5 | H50: 5 | I50: 3 | J50: 3 | K50: =MAX(F50:J50) -> 5 | L50: Completely Isolated | M50: Medium | N50: =CHOOSE(MATCH(INDEX($L$65:$P$69, MATCH(M50, $J$65:$J$69, 0), MATCH(L50, $L$64:$P$64, 0)), {"Very Unlikely","Unlikely","Possible","Likely","Certain"},0),1,2,3,4,5) -> 2 | O50: =max(F50:J50)*N50 -> 10 | P50: =VLOOKUP(O50,SLTS!$A$1:$B$27,2) -> 2 | Q50: Memory protections; integrity measurement; restrict loadable drivers; code signing. | R50: Completely Isolated | S50: Low | T50: =CHOOSE(MATCH(INDEX($L$65:$P$69, MATCH(S50, $J$65:$J$69, 0), MATCH(R50, $L$64:$P$64, 0)), {"Very Unlikely","Unlikely","Possible","Likely","Certain"},0),1,2,3,4,5) -> 1 | U50: =max(F50:J50)*T50 -> 5
M51: Max | N51: =MAX(N4:N7) -> 3 | O51: =MAX(O4:O7) -> 12 | P51: =MAX(P4:P7) -> 2 | T51: =MAX(T4:T7) -> 2 | U51: =MAX(U4:U7) -> 8
J64: Threat Feasibility \ Asset Exposure | L64: Completely Isolated | M64: Highly Restricted | N64: Restricted Access | O64: Easily Accessible | P64: Publicly Accessible
J65: Low | L65: Very Unlikely | M65: Unlikely | N65: Unlikely | O65: Unlikely | P65: Unlikely
J66: Medium | L66: Unlikely | M66: Unlikely | N66: Unlikely | O66: Possible | P66: Possible
J67: High | L67: Unlikely | M67: Unlikely | N67: Possible | O67: Possible | P67: Likely
J68: Extreme High | L68: Unlikely | M68: Possible | N68: Possible | O68: Likely | P68: Likely
J69: Critical | L69: Unlikely | M69: Possible | N69: Likely | O69: Likely | P69: Certain
K584: Consequence | L584: Business (Rep) | M584: Operational (Data Loss) | N584: Financial (Disruption) | O584: Safety (Harm) | P584: Environmental | Q584: Final Impact | R584: AEI | S584: TEF | T584: Unmitigated Likelihood | U584: Unmitigated Risk | V584: SL-T | W584: Countermeasures | X584: AEI (after) | Y584: TEF (after) | Z584: Mitigated Likelihood | AA584: Mitigated Risk
K585: Unauthorized control of SCADA by fake master | L585: 4 | M585: 4 | N585: 5 | O585: 3 | P585: 2 | Q585: 5 | R585: 4 (Easily Accessible) | S585: 4 (High) | T585: Likely (4) | U585: 20 | V585: 4 | W585: Network segmentation, firewall rules, whitelisting master, strict authentication | X585: 3 (Restricted) | Y585: 2 (Medium) | Z585: Unlikely (2) | AA585: 10

Sheet SLTS
A1: Tolerable Risk =6
A2: RISK | B2: SL-T
A3: 1 | B3: 1
A4: 2 | B4: 1
A5: 3 | B5: 1
A6: 4 | B6: 1
A7: 5 | B7: 1
A8: 6 | B8: 1
A9: 7 | B9: 2
A10: 8 | B10: 2
A11: 9 | B11: 2
A12: 10 | B12: 2
A13: 11 | B13: 2
A14: 12 | B14: 2
... A27: 25 | B27: 4

Sheet Sheet16
A1: STRIDE Category | B1: Threat Techniques
A2: Spoofing | B2: Adversary-in-the-Middle
B3: Connection Proxy
B4: Internet Accessible Device
B5: Masquerading
B6: Rogue Master
B7: Spoof Reporting Message
B8: Wireless Compromise
A9: Tampering | B9: Activate Firmware Update Mode
B10: Alarm Suppression
B11: Block Command Message
B12: Block Reporting Message
B13: Change Credential
B14: Change Operating Mode
B15: Manipulate I/O Image
B16: Manipulation of Control
B17: Manipulation of View
B18: Modify Alarm Settings
B19: Modify Controller Tasking
B20: Modify Parameter
B21: Modify Program
... B26: System Firmware
A27: Repudiation | B27: Indicator Removal on Host
B28: Rootkit
B29: Theft of Operational Information
A30: Information Disclosure | B30: Data from Information Repositories
B31: Data from Local System
B32: Detect Operating Mode
B33: Hooking
B34: Network Connection Enumeration
B35: Network Sniffing
B36: Point & Tag Identification
B37: Remote System Discovery
B38: Remote System Information Discovery
B39: Screen Capture
B40: Wireless Sniffing
A41: Denial of Service | B41: Block Serial COM
B42: Brute Force I/O
B43: Damage to Property
B44: Data Destruction
...

Sheet Historian
A2: 1 | B2: Alarm Suppression | C2: The adversary may have to suppress or contend with multiple alarms and/or alarm propagation to achieve a specific goal to evade detection or prevent intended responses from occurring.

Sheet Control Server
A2: 1 | B2: Alarm Suppression | C2: The adversary may have to suppress or contend with multiple alarms and/or alarm propagation to achieve a specific goal to evade detection or prevent intended responses from occurring.

Sheet Data Flow
B2: Block Serial Com | C2: Adversaries may block access to serial COM to prevent instructions or configurations from reaching target devices.
B3: Change Credentials | C3: Adversaries may modify software and device credentials to prevent operator and responder access
B4: Data Destruction | C4: Adversaries may destroy data and files on specific devices or in large numbers to interrupt availability to systems, services, and network resources.
B5: Device Restart/Shutdown | C5: Adversaries may forcibly restart or shutdown a device in an ICS environment to disrupt and potentially negatively impact physical processes.
B6: Network Connection enumeration | C6: Adversaries may perform network connection enumeration to discover information about device communication patterns.
B7: Network Sniffing | C7: An adversary may attempt to sniff the traffic to gain information about the target.
B8: Remote system Discovery | C8: An adversary may attempt to get detailed information about remote systems and their peripherals, such as make/model, role, and configuration.
B9: Remote System Information Discovery | C9: Remote System Information Discovery An adversary may attempt to get detailed information about remote systems and their peripherals, such as make/model, role, and configuration.
B10: Commonly Used Port | C10: Adversaries may communicate over a commonly used port to bypass firewalls or network detection systems and to blend in with normal network activity
B11: Connection Proxy | C11: Adversaries may use a connection proxy to direct network traffic between systems or act as an intermediary for network communications.
B12: Default Credentials
